<?xml version="1.0" ?>
<robot name="hexapod1" xmlns:xacro="http://www.ros.org/wiki/xacro">

<xacro:include filename="$(find hexapod1_description)/urdf/materials.xacro" />
<xacro:include filename="$(find hexapod1_description)/urdf/hexapod1.trans" />
<xacro:include filename="$(find hexapod1_description)/urdf/hexapod1.gazebo" />
<link name="base_link">
  <inertial>
    <origin rpy="0 0 0" xyz="-3.0886578550290464e-17 -9.781969305119851e-17 0.23743381846397166"/>
    <mass value="2.3115326280936817"/>
    <inertia ixx="0.010935" ixy="-0.0" ixz="0.0" iyy="0.010935" iyz="-0.0" izz="0.021858"/>
  </inertial>
  <visual>
    <origin rpy="0 0 0" xyz="0 0 0"/>
    <geometry>
      <mesh filename="package://hexapod1_description/meshes/base_link.stl" scale="0.001 0.001 0.001"/>
    </geometry>
    <material name="silver"/>
  </visual>
  <collision>
    <origin rpy="0 0 0" xyz="0 0 0"/>
    <geometry>
      <mesh filename="package://hexapod1_description/meshes/base_link.stl" scale="0.001 0.001 0.001"/>
    </geometry>
  </collision>
</link>

<link name="lowerleg1_1">
  <inertial>
    <origin rpy="0 0 0" xyz="-0.0012985798550618766 0.0007502320287496311 -0.04902378284752565"/>
    <mass value="0.25197878483643155"/>
    <inertia ixx="0.000211" ixy="-0.0" ixz="0.0" iyy="0.000211" iyz="0.0" izz="1.3e-05"/>
  </inertial>
  <visual>
    <origin rpy="0 0 0" xyz="0.069944 0.124146 -0.109"/>
    <geometry>
      <mesh filename="package://hexapod1_description/meshes/lowerleg1_1.stl" scale="0.001 0.001 0.001"/>
    </geometry>
    <material name="silver"/>
  </visual>
  <collision>
    <origin rpy="0 0 0" xyz="0.069944 0.124146 -0.109"/>
    <geometry>
      <mesh filename="package://hexapod1_description/meshes/lowerleg1_1.stl" scale="0.001 0.001 0.001"/>
    </geometry>
  </collision>
</link>

<link name="kneepin1_1">
  <inertial>
    <origin rpy="0 0 0" xyz="3.4393371566021624e-07 2.3202897624086116e-07 -5.304813255335716e-09"/>
    <mass value="0.002466150233068093"/>
    <inertia ixx="0.0" ixy="0.0" ixz="0.0" iyy="0.0" iyz="-0.0" izz="0.0"/>
  </inertial>
  <visual>
    <origin rpy="0 0 0" xyz="0.073841 0.121896 -0.109"/>
    <geometry>
      <mesh filename="package://hexapod1_description/meshes/kneepin1_1.stl" scale="0.001 0.001 0.001"/>
    </geometry>
    <material name="silver"/>
  </visual>
  <collision>
    <origin rpy="0 0 0" xyz="0.073841 0.121896 -0.109"/>
    <geometry>
      <mesh filename="package://hexapod1_description/meshes/kneepin1_1.stl" scale="0.001 0.001 0.001"/>
    </geometry>
  </collision>
</link>

<link name="upperleg1_1">
  <inertial>
    <origin rpy="0 0 0" xyz="-0.0012987703854457772 0.0007502320252844585 -0.06626668072618791"/>
    <mass value="0.25482988143393986"/>
    <inertia ixx="0.000223" ixy="-0.0" ixz="0.0" iyy="0.000223" iyz="0.0" izz="1.3e-05"/>
  </inertial>
  <visual>
    <origin rpy="0 0 0" xyz="0.076439 0.120396 -0.225"/>
    <geometry>
      <mesh filename="package://hexapod1_description/meshes/upperleg1_1.stl" scale="0.001 0.001 0.001"/>
    </geometry>
    <material name="silver"/>
  </visual>
  <collision>
    <origin rpy="0 0 0" xyz="0.076439 0.120396 -0.225"/>
    <geometry>
      <mesh filename="package://hexapod1_description/meshes/upperleg1_1.stl" scale="0.001 0.001 0.001"/>
    </geometry>
  </collision>
</link>

<link name="thighpin1_1">
  <inertial>
    <origin rpy="0 0 0" xyz="3.4375490172433576e-07 2.317192613898733e-07 1.3877787807814457e-16"/>
    <mass value="0.0024661502330680933"/>
    <inertia ixx="0.0" ixy="0.0" ixz="-0.0" iyy="0.0" iyz="0.0" izz="0.0"/>
  </inertial>
  <visual>
    <origin rpy="0 0 0" xyz="0.073841 0.121896 -0.225"/>
    <geometry>
      <mesh filename="package://hexapod1_description/meshes/thighpin1_1.stl" scale="0.001 0.001 0.001"/>
    </geometry>
    <material name="silver"/>
  </visual>
  <collision>
    <origin rpy="0 0 0" xyz="0.073841 0.121896 -0.225"/>
    <geometry>
      <mesh filename="package://hexapod1_description/meshes/thighpin1_1.stl" scale="0.001 0.001 0.001"/>
    </geometry>
  </collision>
</link>

<link name="lowerleg1_2">
  <inertial>
    <origin rpy="0 0 0" xyz="-0.0012994582506147129 -0.0007497679712503286 -0.04902378284752565"/>
    <mass value="0.25197878483643155"/>
    <inertia ixx="0.000211" ixy="0.0" ixz="-0.0" iyy="0.000211" iyz="0.0" izz="1.3e-05"/>
  </inertial>
  <visual>
    <origin rpy="0 0 0" xyz="-0.071243 0.123396 -0.109"/>
    <geometry>
      <mesh filename="package://hexapod1_description/meshes/lowerleg1_2.stl" scale="0.001 0.001 0.001"/>
    </geometry>
    <material name="silver"/>
  </visual>
  <collision>
    <origin rpy="0 0 0" xyz="-0.071243 0.123396 -0.109"/>
    <geometry>
      <mesh filename="package://hexapod1_description/meshes/lowerleg1_2.stl" scale="0.001 0.001 0.001"/>
    </geometry>
  </collision>
</link>

<link name="kneepin1_2">
  <inertial>
    <origin rpy="0 0 0" xyz="-4.963564221444061e-07 2.3202897626861674e-07 -5.304813255335716e-09"/>
    <mass value="0.002466150233068093"/>
    <inertia ixx="0.0" ixy="-0.0" ixz="0.0" iyy="0.0" iyz="0.0" izz="0.0"/>
  </inertial>
  <visual>
    <origin rpy="0 0 0" xyz="-0.068645 0.124896 -0.109"/>
    <geometry>
      <mesh filename="package://hexapod1_description/meshes/kneepin1_2.stl" scale="0.001 0.001 0.001"/>
    </geometry>
    <material name="silver"/>
  </visual>
  <collision>
    <origin rpy="0 0 0" xyz="-0.068645 0.124896 -0.109"/>
    <geometry>
      <mesh filename="package://hexapod1_description/meshes/kneepin1_2.stl" scale="0.001 0.001 0.001"/>
    </geometry>
  </collision>
</link>

<link name="upperleg1_2">
  <inertial>
    <origin rpy="0 0 0" xyz="-0.001298610671320699 -0.0007497679747154595 -0.06626668072618791"/>
    <mass value="0.25482988143393986"/>
    <inertia ixx="0.000223" ixy="0.0" ixz="-0.0" iyy="0.000223" iyz="0.0" izz="1.3e-05"/>
  </inertial>
  <visual>
    <origin rpy="0 0 0" xyz="-0.066046 0.126396 -0.225"/>
    <geometry>
      <mesh filename="package://hexapod1_description/meshes/upperleg1_2.stl" scale="0.001 0.001 0.001"/>
    </geometry>
    <material name="silver"/>
  </visual>
  <collision>
    <origin rpy="0 0 0" xyz="-0.066046 0.126396 -0.225"/>
    <geometry>
      <mesh filename="package://hexapod1_description/meshes/upperleg1_2.stl" scale="0.001 0.001 0.001"/>
    </geometry>
  </collision>
</link>

<link name="thighpin1_2">
  <inertial>
    <origin rpy="0 0 0" xyz="4.6571671497019906e-07 2.3171926144538446e-07 1.3877787807814457e-16"/>
    <mass value="0.0024661502330680933"/>
    <inertia ixx="0.0" ixy="-0.0" ixz="0.0" iyy="0.0" iyz="0.0" izz="0.0"/>
  </inertial>
  <visual>
    <origin rpy="0 0 0" xyz="-0.067345 0.125646 -0.225"/>
    <geometry>
      <mesh filename="package://hexapod1_description/meshes/thighpin1_2.stl" scale="0.001 0.001 0.001"/>
    </geometry>
    <material name="silver"/>
  </visual>
  <collision>
    <origin rpy="0 0 0" xyz="-0.067345 0.125646 -0.225"/>
    <geometry>
      <mesh filename="package://hexapod1_description/meshes/thighpin1_2.stl" scale="0.001 0.001 0.001"/>
    </geometry>
  </collision>
</link>

<link name="lowerleg1_3">
  <inertial>
    <origin rpy="0 0 0" xyz="1.5971012387594463e-07 -0.001500000000000056 -0.04902378284752565"/>
    <mass value="0.25197878483643155"/>
    <inertia ixx="0.000211" ixy="0.0" ixz="-0.0" iyy="0.000211" iyz="-0.0" izz="1.3e-05"/>
  </inertial>
  <visual>
    <origin rpy="0 0 0" xyz="-0.142485 -0.0015 -0.109"/>
    <geometry>
      <mesh filename="package://hexapod1_description/meshes/lowerleg1_3.stl" scale="0.001 0.001 0.001"/>
    </geometry>
    <material name="silver"/>
  </visual>
  <collision>
    <origin rpy="0 0 0" xyz="-0.142485 -0.0015 -0.109"/>
    <geometry>
      <mesh filename="package://hexapod1_description/meshes/lowerleg1_3.stl" scale="0.001 0.001 0.001"/>
    </geometry>
  </collision>
</link>

<link name="kneepin1_5">
  <inertial>
    <origin rpy="0 0 0" xyz="4.963564222276728e-07 -2.320289764351502e-07 -5.304813255335716e-09"/>
    <mass value="0.002466150233068093"/>
    <inertia ixx="0.0" ixy="-0.0" ixz="0.0" iyy="0.0" iyz="0.0" izz="0.0"/>
  </inertial>
  <visual>
    <origin rpy="0 0 0" xyz="0.068645 -0.124896 -0.109"/>
    <geometry>
      <mesh filename="package://hexapod1_description/meshes/kneepin1_5.stl" scale="0.001 0.001 0.001"/>
    </geometry>
    <material name="silver"/>
  </visual>
  <collision>
    <origin rpy="0 0 0" xyz="0.068645 -0.124896 -0.109"/>
    <geometry>
      <mesh filename="package://hexapod1_description/meshes/kneepin1_5.stl" scale="0.001 0.001 0.001"/>
    </geometry>
  </collision>
</link>

<link name="upperleg1_5">
  <inertial>
    <origin rpy="0 0 0" xyz="0.0012986106713207268 0.0007497679747153208 -0.06626668072618791"/>
    <mass value="0.25482988143393986"/>
    <inertia ixx="0.000223" ixy="0.0" ixz="0.0" iyy="0.000223" iyz="-0.0" izz="1.3e-05"/>
  </inertial>
  <visual>
    <origin rpy="0 0 0" xyz="0.066046 -0.126396 -0.225"/>
    <geometry>
      <mesh filename="package://hexapod1_description/meshes/upperleg1_5.stl" scale="0.001 0.001 0.001"/>
    </geometry>
    <material name="silver"/>
  </visual>
  <collision>
    <origin rpy="0 0 0" xyz="0.066046 -0.126396 -0.225"/>
    <geometry>
      <mesh filename="package://hexapod1_description/meshes/upperleg1_5.stl" scale="0.001 0.001 0.001"/>
    </geometry>
  </collision>
</link>

<link name="thighpin1_5">
  <inertial>
    <origin rpy="0 0 0" xyz="4.961776082224034e-07 -2.317192616257957e-07 1.3877787807814457e-16"/>
    <mass value="0.0024661502330680933"/>
    <inertia ixx="0.0" ixy="-0.0" ixz="-0.0" iyy="0.0" iyz="0.0" izz="0.0"/>
  </inertial>
  <visual>
    <origin rpy="0 0 0" xyz="0.068645 -0.124896 -0.225"/>
    <geometry>
      <mesh filename="package://hexapod1_description/meshes/thighpin1_5.stl" scale="0.001 0.001 0.001"/>
    </geometry>
    <material name="silver"/>
  </visual>
  <collision>
    <origin rpy="0 0 0" xyz="0.068645 -0.124896 -0.225"/>
    <geometry>
      <mesh filename="package://hexapod1_description/meshes/thighpin1_5.stl" scale="0.001 0.001 0.001"/>
    </geometry>
  </collision>
</link>

<link name="lowerleg1_6">
  <inertial>
    <origin rpy="0 0 0" xyz="-1.5971012387594463e-07 0.001499999999999964 -0.049023782847525364"/>
    <mass value="0.25197878483643155"/>
    <inertia ixx="0.000211" ixy="0.0" ixz="0.0" iyy="0.000211" iyz="0.0" izz="1.3e-05"/>
  </inertial>
  <visual>
    <origin rpy="0 0 0" xyz="0.142485 0.0 -0.109"/>
    <geometry>
      <mesh filename="package://hexapod1_description/meshes/lowerleg1_6.stl" scale="0.001 0.001 0.001"/>
    </geometry>
    <material name="silver"/>
  </visual>
  <collision>
    <origin rpy="0 0 0" xyz="0.142485 0.0 -0.109"/>
    <geometry>
      <mesh filename="package://hexapod1_description/meshes/lowerleg1_6.stl" scale="0.001 0.001 0.001"/>
    </geometry>
  </collision>
</link>

<link name="kneepin1_6">
  <inertial>
    <origin rpy="0 0 0" xyz="-1.5970986219637773e-07 -4.683753385137379e-17 -5.30481297777996e-09"/>
    <mass value="0.002466150233068093"/>
    <inertia ixx="0.0" ixy="-0.0" ixz="0.0" iyy="0.0" iyz="0.0" izz="0.0"/>
  </inertial>
  <visual>
    <origin rpy="0 0 0" xyz="0.142485 -0.0045 -0.109"/>
    <geometry>
      <mesh filename="package://hexapod1_description/meshes/kneepin1_6.stl" scale="0.001 0.001 0.001"/>
    </geometry>
    <material name="silver"/>
  </visual>
  <collision>
    <origin rpy="0 0 0" xyz="0.142485 -0.0045 -0.109"/>
    <geometry>
      <mesh filename="package://hexapod1_description/meshes/kneepin1_6.stl" scale="0.001 0.001 0.001"/>
    </geometry>
  </collision>
</link>

<link name="upperleg1_6">
  <inertial>
    <origin rpy="0 0 0" xyz="-1.5971412506421423e-07 0.0014999999999999458 -0.06626668072618791"/>
    <mass value="0.25482988143393986"/>
    <inertia ixx="0.000222" ixy="0.0" ixz="0.0" iyy="0.000223" iyz="0.0" izz="1.3e-05"/>
  </inertial>
  <visual>
    <origin rpy="0 0 0" xyz="0.142485 -0.006 -0.225"/>
    <geometry>
      <mesh filename="package://hexapod1_description/meshes/upperleg1_6.stl" scale="0.001 0.001 0.001"/>
    </geometry>
    <material name="silver"/>
  </visual>
  <collision>
    <origin rpy="0 0 0" xyz="0.142485 -0.006 -0.225"/>
    <geometry>
      <mesh filename="package://hexapod1_description/meshes/upperleg1_6.stl" scale="0.001 0.001 0.001"/>
    </geometry>
  </collision>
</link>

<link name="thighpin1_6">
  <inertial>
    <origin rpy="0 0 0" xyz="-1.6006749009589427e-07 -6.635317295611287e-17 1.3877787807814457e-16"/>
    <mass value="0.0024661502330680933"/>
    <inertia ixx="0.0" ixy="0.0" ixz="-0.0" iyy="0.0" iyz="-0.0" izz="0.0"/>
  </inertial>
  <visual>
    <origin rpy="0 0 0" xyz="0.142485 -0.003 -0.225"/>
    <geometry>
      <mesh filename="package://hexapod1_description/meshes/thighpin1_6.stl" scale="0.001 0.001 0.001"/>
    </geometry>
    <material name="silver"/>
  </visual>
  <collision>
    <origin rpy="0 0 0" xyz="0.142485 -0.003 -0.225"/>
    <geometry>
      <mesh filename="package://hexapod1_description/meshes/thighpin1_6.stl" scale="0.001 0.001 0.001"/>
    </geometry>
  </collision>
</link>

<link name="lowerleg1_5">
  <inertial>
    <origin rpy="0 0 0" xyz="-0.0012985798550619182 -0.0007502320287498532 -0.04902378284752565"/>
    <mass value="0.25197878483643155"/>
    <inertia ixx="0.000211" ixy="0.0" ixz="0.0" iyy="0.000211" iyz="-0.0" izz="1.3e-05"/>
  </inertial>
  <visual>
    <origin rpy="0 0 0" xyz="0.069944 -0.124146 -0.109"/>
    <geometry>
      <mesh filename="package://hexapod1_description/meshes/lowerleg1_5.stl" scale="0.001 0.001 0.001"/>
    </geometry>
    <material name="silver"/>
  </visual>
  <collision>
    <origin rpy="0 0 0" xyz="0.069944 -0.124146 -0.109"/>
    <geometry>
      <mesh filename="package://hexapod1_description/meshes/lowerleg1_5.stl" scale="0.001 0.001 0.001"/>
    </geometry>
  </collision>
</link>

<link name="kneepin1_3">
  <inertial>
    <origin rpy="0 0 0" xyz="1.5970986219637773e-07 -4.683753385137379e-17 -5.304813255335716e-09"/>
    <mass value="0.002466150233068093"/>
    <inertia ixx="0.0" ixy="-0.0" ixz="0.0" iyy="0.0" iyz="0.0" izz="0.0"/>
  </inertial>
  <visual>
    <origin rpy="0 0 0" xyz="-0.142485 0.003 -0.109"/>
    <geometry>
      <mesh filename="package://hexapod1_description/meshes/kneepin1_3.stl" scale="0.001 0.001 0.001"/>
    </geometry>
    <material name="silver"/>
  </visual>
  <collision>
    <origin rpy="0 0 0" xyz="-0.142485 0.003 -0.109"/>
    <geometry>
      <mesh filename="package://hexapod1_description/meshes/kneepin1_3.stl" scale="0.001 0.001 0.001"/>
    </geometry>
  </collision>
</link>

<link name="upperleg1_3">
  <inertial>
    <origin rpy="0 0 0" xyz="1.5971412511972538e-07 -0.0015000000000000464 -0.06626668072618791"/>
    <mass value="0.25482988143393986"/>
    <inertia ixx="0.000222" ixy="-0.0" ixz="-0.0" iyy="0.000223" iyz="-0.0" izz="1.3e-05"/>
  </inertial>
  <visual>
    <origin rpy="0 0 0" xyz="-0.142485 0.006 -0.225"/>
    <geometry>
      <mesh filename="package://hexapod1_description/meshes/upperleg1_3.stl" scale="0.001 0.001 0.001"/>
    </geometry>
    <material name="silver"/>
  </visual>
  <collision>
    <origin rpy="0 0 0" xyz="-0.142485 0.006 -0.225"/>
    <geometry>
      <mesh filename="package://hexapod1_description/meshes/upperleg1_3.stl" scale="0.001 0.001 0.001"/>
    </geometry>
  </collision>
</link>

<link name="thighpin1_3">
  <inertial>
    <origin rpy="0 0 0" xyz="1.6006749012364985e-07 -1.8214596497756474e-17 1.3877787807814457e-16"/>
    <mass value="0.0024661502330680933"/>
    <inertia ixx="0.0" ixy="0.0" ixz="0.0" iyy="0.0" iyz="-0.0" izz="0.0"/>
  </inertial>
  <visual>
    <origin rpy="0 0 0" xyz="-0.142485 0.003 -0.225"/>
    <geometry>
      <mesh filename="package://hexapod1_description/meshes/thighpin1_3.stl" scale="0.001 0.001 0.001"/>
    </geometry>
    <material name="silver"/>
  </visual>
  <collision>
    <origin rpy="0 0 0" xyz="-0.142485 0.003 -0.225"/>
    <geometry>
      <mesh filename="package://hexapod1_description/meshes/thighpin1_3.stl" scale="0.001 0.001 0.001"/>
    </geometry>
  </collision>
</link>

<link name="lowerleg1_4">
  <inertial>
    <origin rpy="0 0 0" xyz="0.0012985798550619182 -0.0007502320287498532 -0.04902378284752565"/>
    <mass value="0.25197878483643155"/>
    <inertia ixx="0.000211" ixy="-0.0" ixz="-0.0" iyy="0.000211" iyz="-0.0" izz="1.3e-05"/>
  </inertial>
  <visual>
    <origin rpy="0 0 0" xyz="-0.069944 -0.124146 -0.109"/>
    <geometry>
      <mesh filename="package://hexapod1_description/meshes/lowerleg1_4.stl" scale="0.001 0.001 0.001"/>
    </geometry>
    <material name="silver"/>
  </visual>
  <collision>
    <origin rpy="0 0 0" xyz="-0.069944 -0.124146 -0.109"/>
    <geometry>
      <mesh filename="package://hexapod1_description/meshes/lowerleg1_4.stl" scale="0.001 0.001 0.001"/>
    </geometry>
  </collision>
</link>

<link name="kneepin1_4">
  <inertial>
    <origin rpy="0 0 0" xyz="-3.439337156047051e-07 -2.3202897646290577e-07 -5.304813255335716e-09"/>
    <mass value="0.002466150233068093"/>
    <inertia ixx="0.0" ixy="0.0" ixz="0.0" iyy="0.0" iyz="0.0" izz="0.0"/>
  </inertial>
  <visual>
    <origin rpy="0 0 0" xyz="-0.073841 -0.121896 -0.109"/>
    <geometry>
      <mesh filename="package://hexapod1_description/meshes/kneepin1_4.stl" scale="0.001 0.001 0.001"/>
    </geometry>
    <material name="silver"/>
  </visual>
  <collision>
    <origin rpy="0 0 0" xyz="-0.073841 -0.121896 -0.109"/>
    <geometry>
      <mesh filename="package://hexapod1_description/meshes/kneepin1_4.stl" scale="0.001 0.001 0.001"/>
    </geometry>
  </collision>
</link>

<link name="upperleg1_4">
  <inertial>
    <origin rpy="0 0 0" xyz="0.001298770385445791 -0.000750232025284639 -0.06626668072618791"/>
    <mass value="0.25482988143393986"/>
    <inertia ixx="0.000223" ixy="-0.0" ixz="-0.0" iyy="0.000223" iyz="-0.0" izz="1.3e-05"/>
  </inertial>
  <visual>
    <origin rpy="0 0 0" xyz="-0.076439 -0.120396 -0.225"/>
    <geometry>
      <mesh filename="package://hexapod1_description/meshes/upperleg1_4.stl" scale="0.001 0.001 0.001"/>
    </geometry>
    <material name="silver"/>
  </visual>
  <collision>
    <origin rpy="0 0 0" xyz="-0.076439 -0.120396 -0.225"/>
    <geometry>
      <mesh filename="package://hexapod1_description/meshes/upperleg1_4.stl" scale="0.001 0.001 0.001"/>
    </geometry>
  </collision>
</link>

<link name="thighpin1_4">
  <inertial>
    <origin rpy="0 0 0" xyz="-3.437549016965802e-07 -2.3171926157028455e-07 1.3877787807814457e-16"/>
    <mass value="0.0024661502330680933"/>
    <inertia ixx="0.0" ixy="0.0" ixz="0.0" iyy="0.0" iyz="0.0" izz="0.0"/>
  </inertial>
  <visual>
    <origin rpy="0 0 0" xyz="-0.073841 -0.121896 -0.225"/>
    <geometry>
      <mesh filename="package://hexapod1_description/meshes/thighpin1_4.stl" scale="0.001 0.001 0.001"/>
    </geometry>
    <material name="silver"/>
  </visual>
  <collision>
    <origin rpy="0 0 0" xyz="-0.073841 -0.121896 -0.225"/>
    <geometry>
      <mesh filename="package://hexapod1_description/meshes/thighpin1_4.stl" scale="0.001 0.001 0.001"/>
    </geometry>
  </collision>
</link>

<joint name="Rigid1" type="fixed">
  <origin rpy="0 0 0" xyz="0.003897 -0.00225 0.0"/>
  <parent link="kneepin1_1"/>
  <child link="lowerleg1_1"/>
</joint>

<joint name="Rev1" type="revolute">
  <origin rpy="0 0 0" xyz="0.002598 -0.0015 -0.116"/>
  <parent link="upperleg1_1"/>
  <child link="kneepin1_1"/>
  <axis xyz="0.866025 -0.5 -0.0"/>
  <limit effort="100" lower="0.0" upper="0.785398" velocity="100"/>
</joint>

<joint name="Rigid2" type="fixed">
  <origin rpy="0 0 0" xyz="-0.002598 0.0015 0.0"/>
  <parent link="thighpin1_1"/>
  <child link="upperleg1_1"/>
</joint>

<joint name="Rev2" type="revolute">
  <origin rpy="0 0 0" xyz="-0.073841 -0.121896 0.225"/>
  <parent link="base_link"/>
  <child link="thighpin1_1"/>
  <axis xyz="0.866025 -0.5 -0.0"/>
  <limit effort="100" lower="-0.785398" upper="0.0" velocity="100"/>
</joint>

<joint name="Rigid3" type="fixed">
  <origin rpy="0 0 0" xyz="0.002598 0.0015 0.0"/>
  <parent link="kneepin1_2"/>
  <child link="lowerleg1_2"/>
</joint>

<joint name="Rev3" type="revolute">
  <origin rpy="0 0 0" xyz="0.002599 0.0015 -0.116"/>
  <parent link="upperleg1_2"/>
  <child link="kneepin1_2"/>
  <axis xyz="0.866025 0.5 -0.0"/>
  <limit effort="100" lower="0.0" upper="0.785398" velocity="100"/>
</joint>

<joint name="Rigid4" type="fixed">
  <origin rpy="0 0 0" xyz="-0.001299 -0.00075 0.0"/>
  <parent link="thighpin1_2"/>
  <child link="upperleg1_2"/>
</joint>

<joint name="Rev4" type="revolute">
  <origin rpy="0 0 0" xyz="0.067345 -0.125646 0.225"/>
  <parent link="base_link"/>
  <child link="thighpin1_2"/>
  <axis xyz="0.866025 0.5 0.0"/>
  <limit effort="100" lower="-0.785398" upper="0.0" velocity="100"/>
</joint>

<joint name="Rigid9" type="fixed">
  <origin rpy="0 0 0" xyz="0.0 0.0045 0.0"/>
  <parent link="kneepin1_3"/>
  <child link="lowerleg1_3"/>
</joint>

<joint name="Rev5" type="revolute">
  <origin rpy="0 0 0" xyz="-0.002599 -0.0015 -0.116"/>
  <parent link="upperleg1_5"/>
  <child link="kneepin1_5"/>
  <axis xyz="-0.866025 -0.5 -0.0"/>
  <limit effort="100" lower="0.0" upper="0.785398" velocity="100"/>
</joint>

<joint name="Rigid6" type="fixed">
  <origin rpy="0 0 0" xyz="0.002599 0.0015 0.0"/>
  <parent link="thighpin1_5"/>
  <child link="upperleg1_5"/>
</joint>

<joint name="Rev6" type="revolute">
  <origin rpy="0 0 0" xyz="-0.068645 0.124896 0.225"/>
  <parent link="base_link"/>
  <child link="thighpin1_5"/>
  <axis xyz="-0.866025 -0.5 -0.0"/>
  <limit effort="100" lower="5.497787" upper="6.283185" velocity="100"/>
</joint>

<joint name="Rigid7" type="fixed">
  <origin rpy="0 0 0" xyz="0.0 -0.0045 0.0"/>
  <parent link="kneepin1_6"/>
  <child link="lowerleg1_6"/>
</joint>

<joint name="Rev7" type="revolute">
  <origin rpy="0 0 0" xyz="0.0 -0.0015 -0.116"/>
  <parent link="upperleg1_6"/>
  <child link="kneepin1_6"/>
  <axis xyz="-0.0 -1.0 -0.0"/>
  <limit effort="100" lower="0.0" upper="0.785398" velocity="100"/>
</joint>

<joint name="Rigid8" type="fixed">
  <origin rpy="0 0 0" xyz="0.0 0.003 0.0"/>
  <parent link="thighpin1_6"/>
  <child link="upperleg1_6"/>
</joint>

<joint name="Rev8" type="revolute">
  <origin rpy="0 0 0" xyz="-0.142485 0.003 0.225"/>
  <parent link="base_link"/>
  <child link="thighpin1_6"/>
  <axis xyz="-0.0 -1.0 -0.0"/>
  <limit effort="100" lower="-0.785398" upper="0.0" velocity="100"/>
</joint>

<joint name="Rigid5" type="fixed">
  <origin rpy="0 0 0" xyz="-0.001299 -0.00075 0.0"/>
  <parent link="kneepin1_5"/>
  <child link="lowerleg1_5"/>
</joint>

<joint name="Rev24" type="revolute">
  <origin rpy="0 0 0" xyz="0.0 0.003 -0.116"/>
  <parent link="upperleg1_3"/>
  <child link="kneepin1_3"/>
  <axis xyz="0.0 1.0 -0.0"/>
  <limit effort="100" lower="0.0" upper="0.785398" velocity="100"/>
</joint>

<joint name="Rigid25" type="fixed">
  <origin rpy="0 0 0" xyz="0.0 -0.003 0.0"/>
  <parent link="thighpin1_3"/>
  <child link="upperleg1_3"/>
</joint>

<joint name="Rev26" type="revolute">
  <origin rpy="0 0 0" xyz="0.142485 -0.003 0.225"/>
  <parent link="base_link"/>
  <child link="thighpin1_3"/>
  <axis xyz="-0.0 1.0 0.0"/>
  <limit effort="100" lower="-0.785398" upper="0.0" velocity="100"/>
</joint>

<joint name="Rigid27" type="fixed">
  <origin rpy="0 0 0" xyz="-0.003897 0.00225 0.0"/>
  <parent link="kneepin1_4"/>
  <child link="lowerleg1_4"/>
</joint>

<joint name="Rev28" type="revolute">
  <origin rpy="0 0 0" xyz="-0.002598 0.0015 -0.116"/>
  <parent link="upperleg1_4"/>
  <child link="kneepin1_4"/>
  <axis xyz="-0.866025 0.5 -0.0"/>
  <limit effort="100" lower="0.0" upper="0.785398" velocity="100"/>
</joint>

<joint name="Rigid29" type="fixed">
  <origin rpy="0 0 0" xyz="0.002598 -0.0015 0.0"/>
  <parent link="thighpin1_4"/>
  <child link="upperleg1_4"/>
</joint>

<joint name="Rev30" type="continuous">
  <origin rpy="0 0 0" xyz="0.073841 0.121896 0.225"/>
  <parent link="base_link"/>
  <child link="thighpin1_4"/>
  <axis xyz="-0.866025 0.5 0.0"/>
</joint>

</robot>
