<?xml version="1.0" ?>
<robot name="improvedesign" xmlns:xacro="http://www.ros.org/wiki/xacro">

<xacro:include filename="$(find improvedesign_description)/urdf/materials.xacro" />
<xacro:include filename="$(find improvedesign_description)/urdf/improvedesign.trans" />
<xacro:include filename="$(find improvedesign_description)/gazebo/improvedesign_materials.gazebo" />
<xacro:include filename="$(find improvedesign_description)/gazebo/improvedesign_physics.gazebo" />
<xacro:include filename="$(find improvedesign_description)/gazebo/improvedesign_plugins.gazebo" />

<link name="base_link">
  <inertial>
    <origin rpy="0 0 0" xyz="-2.7797920695261423e-16 1.6275392110627996e-16 0.2408070750718569"/>
    <mass value="2.311532628093681"/>
    <inertia ixx="0.010895" ixy="0.0" ixz="0.0" iyy="0.010895" iyz="0.0" izz="0.021777"/>
  </inertial>
  <visual>
    <origin rpy="0 0 0" xyz="0 0 0"/>
    <geometry>
      <mesh filename="package://improvedesign_description/meshes/base_link.stl" scale="0.001 0.001 0.001"/>
    </geometry>
    <material name="silver"/>
  </visual>
  <collision>
    <origin rpy="0 0 0" xyz="0 0 0"/>
    <geometry>
      <mesh filename="package://improvedesign_description/meshes/base_link.stl" scale="0.001 0.001 0.001"/>
    </geometry>
  </collision>
</link>

<link name="lowerleg1">
  <inertial>
    <origin rpy="0 0 0" xyz="0.0014999999999999142 1.8978996156604477e-07 -0.049023526239640056"/>
    <mass value="0.25197878483643155"/>
    <inertia ixx="0.000211" ixy="0.0" ixz="-0.0" iyy="0.000211" iyz="0.0" izz="1.3e-05"/>
  </inertial>
  <visual>
    <origin rpy="0 0 0" xyz="0.0015 0.124904 -0.112373"/>
    <geometry>
      <mesh filename="package://improvedesign_description/meshes/lowerleg1.stl" scale="0.001 0.001 0.001"/>
    </geometry>
    <material name="silver"/>
  </visual>
  <collision>
    <origin rpy="0 0 0" xyz="0.0015 0.124904 -0.112373"/>
    <geometry>
      <mesh filename="package://improvedesign_description/meshes/lowerleg1.stl" scale="0.001 0.001 0.001"/>
    </geometry>
  </collision>
</link>

<link name="upperleg2">
  <inertial>
    <origin rpy="0 0 0" xyz="0.0007498726713631859 0.0012990948949807915 -0.04902352623964014"/>
    <mass value="0.2519787848364315"/>
    <inertia ixx="0.000211" ixy="0.0" ixz="-0.0" iyy="0.000211" iyz="0.0" izz="1.3e-05"/>
  </inertial>
  <visual>
    <origin rpy="0 0 0" xyz="-0.10742 0.063751 -0.112373"/>
    <geometry>
      <mesh filename="package://improvedesign_description/meshes/upperleg2.stl" scale="0.001 0.001 0.001"/>
    </geometry>
    <material name="silver"/>
  </visual>
  <collision>
    <origin rpy="0 0 0" xyz="-0.10742 0.063751 -0.112373"/>
    <geometry>
      <mesh filename="package://improvedesign_description/meshes/upperleg2.stl" scale="0.001 0.001 0.001"/>
    </geometry>
  </collision>
</link>

<link name="lowerleg4">
  <inertial>
    <origin rpy="0 0 0" xyz="0.0007501273286365934 -0.0012989051050190312 -0.04902352623964018"/>
    <mass value="0.25197878483643155"/>
    <inertia ixx="0.000211" ixy="-0.0" ixz="0.0" iyy="0.000211" iyz="0.0" izz="1.3e-05"/>
  </inertial>
  <visual>
    <origin rpy="0 0 0" xyz="0.10892 0.061153 -0.112373"/>
    <geometry>
      <mesh filename="package://improvedesign_description/meshes/lowerleg4.stl" scale="0.001 0.001 0.001"/>
    </geometry>
    <material name="silver"/>
  </visual>
  <collision>
    <origin rpy="0 0 0" xyz="0.10892 0.061153 -0.112373"/>
    <geometry>
      <mesh filename="package://improvedesign_description/meshes/lowerleg4.stl" scale="0.001 0.001 0.001"/>
    </geometry>
  </collision>
</link>

<link name="lowerleg3">
  <inertial>
    <origin rpy="0 0 0" xyz="0.0007498732907923605 -0.0012990945373532112 -0.04902352623964021"/>
    <mass value="0.2519787848364316"/>
    <inertia ixx="0.000211" ixy="-0.0" ixz="0.0" iyy="0.000211" iyz="0.0" izz="1.3e-05"/>
  </inertial>
  <visual>
    <origin rpy="0 0 0" xyz="-0.10742 -0.063751 -0.112373"/>
    <geometry>
      <mesh filename="package://improvedesign_description/meshes/lowerleg3.stl" scale="0.001 0.001 0.001"/>
    </geometry>
    <material name="silver"/>
  </visual>
  <collision>
    <origin rpy="0 0 0" xyz="-0.10742 -0.063751 -0.112373"/>
    <geometry>
      <mesh filename="package://improvedesign_description/meshes/lowerleg3.stl" scale="0.001 0.001 0.001"/>
    </geometry>
  </collision>
</link>

<link name="lowerleg6">
  <inertial>
    <origin rpy="0 0 0" xyz="0.0014999999999999645 -1.8907470664131232e-07 -0.04902352623964021"/>
    <mass value="0.25197878483643155"/>
    <inertia ixx="0.000211" ixy="-0.0" ixz="-0.0" iyy="0.000211" iyz="0.0" izz="1.3e-05"/>
  </inertial>
  <visual>
    <origin rpy="0 0 0" xyz="0.0015 -0.124904 -0.112373"/>
    <geometry>
      <mesh filename="package://improvedesign_description/meshes/lowerleg6.stl" scale="0.001 0.001 0.001"/>
    </geometry>
    <material name="silver"/>
  </visual>
  <collision>
    <origin rpy="0 0 0" xyz="0.0015 -0.124904 -0.112373"/>
    <geometry>
      <mesh filename="package://improvedesign_description/meshes/lowerleg6.stl" scale="0.001 0.001 0.001"/>
    </geometry>
  </collision>
</link>

<link name="lowerleg5">
  <inertial>
    <origin rpy="0 0 0" xyz="0.0007501267092076824 0.0012989054626466323 -0.049023526239640236"/>
    <mass value="0.25197878483643155"/>
    <inertia ixx="0.000211" ixy="0.0" ixz="-0.0" iyy="0.000211" iyz="0.0" izz="1.3e-05"/>
  </inertial>
  <visual>
    <origin rpy="0 0 0" xyz="0.10892 -0.061153 -0.112373"/>
    <geometry>
      <mesh filename="package://improvedesign_description/meshes/lowerleg5.stl" scale="0.001 0.001 0.001"/>
    </geometry>
    <material name="silver"/>
  </visual>
  <collision>
    <origin rpy="0 0 0" xyz="0.10892 -0.061153 -0.112373"/>
    <geometry>
      <mesh filename="package://improvedesign_description/meshes/lowerleg5.stl" scale="0.001 0.001 0.001"/>
    </geometry>
  </collision>
</link>

<link name="upperleg6">
  <inertial>
    <origin rpy="0 0 0" xyz="-0.001500000000000007 -1.8907870720508146e-07 -0.06626642411830211"/>
    <mass value="0.25482988143393964"/>
    <inertia ixx="0.000223" ixy="-0.0" ixz="0.0" iyy="0.000222" iyz="0.0" izz="1.3e-05"/>
  </inertial>
  <visual>
    <origin rpy="0 0 0" xyz="0.0015 -0.124904 -0.228373"/>
    <geometry>
      <mesh filename="package://improvedesign_description/meshes/upperleg6.stl" scale="0.001 0.001 0.001"/>
    </geometry>
    <material name="silver"/>
  </visual>
  <collision>
    <origin rpy="0 0 0" xyz="0.0015 -0.124904 -0.228373"/>
    <geometry>
      <mesh filename="package://improvedesign_description/meshes/upperleg6.stl" scale="0.001 0.001 0.001"/>
    </geometry>
  </collision>
</link>

<link name="upperleg3">
  <inertial>
    <origin rpy="0 0 0" xyz="-0.0007501267126726469 0.001298981671999641 -0.0662664241183023"/>
    <mass value="0.2548298814339397"/>
    <inertia ixx="0.000223" ixy="-0.0" ixz="0.0" iyy="0.000223" iyz="0.0" izz="1.3e-05"/>
  </inertial>
  <visual>
    <origin rpy="0 0 0" xyz="-0.10742 -0.063751 -0.228373"/>
    <geometry>
      <mesh filename="package://improvedesign_description/meshes/upperleg3.stl" scale="0.001 0.001 0.001"/>
    </geometry>
    <material name="silver"/>
  </visual>
  <collision>
    <origin rpy="0 0 0" xyz="-0.10742 -0.063751 -0.228373"/>
    <geometry>
      <mesh filename="package://improvedesign_description/meshes/upperleg3.stl" scale="0.001 0.001 0.001"/>
    </geometry>
  </collision>
</link>

<link name="upperleg1">
  <inertial>
    <origin rpy="0 0 0" xyz="-0.0015000000000000438 1.8978596048879748e-07 -0.06626642411830236"/>
    <mass value="0.25482988143393986"/>
    <inertia ixx="0.000223" ixy="0.0" ixz="-0.0" iyy="0.000222" iyz="0.0" izz="1.3e-05"/>
  </inertial>
  <visual>
    <origin rpy="0 0 0" xyz="0.0015 0.124904 -0.228373"/>
    <geometry>
      <mesh filename="package://improvedesign_description/meshes/upperleg1.stl" scale="0.001 0.001 0.001"/>
    </geometry>
    <material name="silver"/>
  </visual>
  <collision>
    <origin rpy="0 0 0" xyz="0.0015 0.124904 -0.228373"/>
    <geometry>
      <mesh filename="package://improvedesign_description/meshes/upperleg1.stl" scale="0.001 0.001 0.001"/>
    </geometry>
  </collision>
</link>

<link name="upperleg5">
  <inertial>
    <origin rpy="0 0 0" xyz="-0.000749873287327521 -0.001299170750706527 -0.06626642411830222"/>
    <mass value="0.25482988143393964"/>
    <inertia ixx="0.000223" ixy="0.0" ixz="-0.0" iyy="0.000223" iyz="0.0" izz="1.3e-05"/>
  </inertial>
  <visual>
    <origin rpy="0 0 0" xyz="0.10892 -0.061153 -0.228373"/>
    <geometry>
      <mesh filename="package://improvedesign_description/meshes/upperleg5.stl" scale="0.001 0.001 0.001"/>
    </geometry>
    <material name="silver"/>
  </visual>
  <collision>
    <origin rpy="0 0 0" xyz="0.10892 -0.061153 -0.228373"/>
    <geometry>
      <mesh filename="package://improvedesign_description/meshes/upperleg5.stl" scale="0.001 0.001 0.001"/>
    </geometry>
  </collision>
</link>

<link name="lowerleg2">
  <inertial>
    <origin rpy="0 0 0" xyz="-0.0007501273251715596 -0.0012989813183730409 -0.0662664241183025"/>
    <mass value="0.2548298814339398"/>
    <inertia ixx="0.000223" ixy="0.0" ixz="-0.0" iyy="0.000223" iyz="0.0" izz="1.3e-05"/>
  </inertial>
  <visual>
    <origin rpy="0 0 0" xyz="-0.10742 0.063751 -0.228373"/>
    <geometry>
      <mesh filename="package://improvedesign_description/meshes/lowerleg2.stl" scale="0.001 0.001 0.001"/>
    </geometry>
    <material name="silver"/>
  </visual>
  <collision>
    <origin rpy="0 0 0" xyz="-0.10742 0.063751 -0.228373"/>
    <geometry>
      <mesh filename="package://improvedesign_description/meshes/lowerleg2.stl" scale="0.001 0.001 0.001"/>
    </geometry>
  </collision>
</link>

<link name="upperleg4">
  <inertial>
    <origin rpy="0 0 0" xyz="-0.0007498726748281365 0.0012991711043335158 -0.0662664241183023"/>
    <mass value="0.25482988143393964"/>
    <inertia ixx="0.000223" ixy="-0.0" ixz="0.0" iyy="0.000223" iyz="0.0" izz="1.3e-05"/>
  </inertial>
  <visual>
    <origin rpy="0 0 0" xyz="0.10892 0.061153 -0.228373"/>
    <geometry>
      <mesh filename="package://improvedesign_description/meshes/upperleg4.stl" scale="0.001 0.001 0.001"/>
    </geometry>
    <material name="silver"/>
  </visual>
  <collision>
    <origin rpy="0 0 0" xyz="0.10892 0.061153 -0.228373"/>
    <geometry>
      <mesh filename="package://improvedesign_description/meshes/upperleg4.stl" scale="0.001 0.001 0.001"/>
    </geometry>
  </collision>
</link>

<link name="kneepin1">
  <inertial>
    <origin rpy="0 0 0" xyz="-6.223320470066795e-17 1.8979022325948947e-07 2.5130307232390514e-07"/>
    <mass value="0.0024661502330680933"/>
    <inertia ixx="0.0" ixy="0.0" ixz="0.0" iyy="0.0" iyz="0.0" izz="0.0"/>
  </inertial>
  <visual>
    <origin rpy="0 0 0" xyz="-0.0015 0.124904 -0.112373"/>
    <geometry>
      <mesh filename="package://improvedesign_description/meshes/kneepin1.stl" scale="0.001 0.001 0.001"/>
    </geometry>
    <material name="silver"/>
  </visual>
  <collision>
    <origin rpy="0 0 0" xyz="-0.0015 0.124904 -0.112373"/>
    <geometry>
      <mesh filename="package://improvedesign_description/meshes/kneepin1.stl" scale="0.001 0.001 0.001"/>
    </geometry>
  </collision>
</link>

<link name="thighpin1">
  <inertial>
    <origin rpy="0 0 0" xyz="-1.235990476633475e-17 1.8943259555426195e-07 2.5660788557924086e-07"/>
    <mass value="0.002466150233068093"/>
    <inertia ixx="0.0" ixy="0.0" ixz="0.0" iyy="0.0" iyz="0.0" izz="0.0"/>
  </inertial>
  <visual>
    <origin rpy="0 0 0" xyz="0.0015 0.124904 -0.228373"/>
    <geometry>
      <mesh filename="package://improvedesign_description/meshes/thighpin1.stl" scale="0.001 0.001 0.001"/>
    </geometry>
    <material name="silver"/>
  </visual>
  <collision>
    <origin rpy="0 0 0" xyz="0.0015 0.124904 -0.228373"/>
    <geometry>
      <mesh filename="package://improvedesign_description/meshes/thighpin1.stl" scale="0.001 0.001 0.001"/>
    </geometry>
  </collision>
</link>

<link name="thighpin2">
  <inertial>
    <origin rpy="0 0 0" xyz="-1.2732886342514682e-07 1.3300078832712003e-07 2.51303072268394e-07"/>
    <mass value="0.0024661502330680938"/>
    <inertia ixx="0.0" ixy="-0.0" ixz="0.0" iyy="0.0" iyz="0.0" izz="0.0"/>
  </inertial>
  <visual>
    <origin rpy="0 0 0" xyz="-0.10892 0.061153 -0.112373"/>
    <geometry>
      <mesh filename="package://improvedesign_description/meshes/thighpin2.stl" scale="0.001 0.001 0.001"/>
    </geometry>
    <material name="silver"/>
  </visual>
  <collision>
    <origin rpy="0 0 0" xyz="-0.10892 0.061153 -0.112373"/>
    <geometry>
      <mesh filename="package://improvedesign_description/meshes/thighpin2.stl" scale="0.001 0.001 0.001"/>
    </geometry>
  </collision>
</link>

<link name="kneepin2">
  <inertial>
    <origin rpy="0 0 0" xyz="-1.2701914849089224e-07 5.661062130180028e-08 2.5660788546821856e-07"/>
    <mass value="0.0024661502330680938"/>
    <inertia ixx="0.0" ixy="-0.0" ixz="-0.0" iyy="0.0" iyz="0.0" izz="0.0"/>
  </inertial>
  <visual>
    <origin rpy="0 0 0" xyz="-0.10742 0.063751 -0.228373"/>
    <geometry>
      <mesh filename="package://improvedesign_description/meshes/kneepin2.stl" scale="0.001 0.001 0.001"/>
    </geometry>
    <material name="silver"/>
  </visual>
  <collision>
    <origin rpy="0 0 0" xyz="-0.10742 0.063751 -0.228373"/>
    <geometry>
      <mesh filename="package://improvedesign_description/meshes/kneepin2.stl" scale="0.001 0.001 0.001"/>
    </geometry>
  </collision>
</link>

<link name="kneepin3">
  <inertial>
    <origin rpy="0 0 0" xyz="-1.2670898100197725e-07 -1.3264289894232562e-07 2.5130307222676063e-07"/>
    <mass value="0.002466150233068093"/>
    <inertia ixx="0.0" ixy="0.0" ixz="0.0" iyy="0.0" iyz="0.0" izz="0.0"/>
  </inertial>
  <visual>
    <origin rpy="0 0 0" xyz="-0.10892 -0.061153 -0.112373"/>
    <geometry>
      <mesh filename="package://improvedesign_description/meshes/kneepin3.stl" scale="0.001 0.001 0.001"/>
    </geometry>
    <material name="silver"/>
  </visual>
  <collision>
    <origin rpy="0 0 0" xyz="-0.10892 -0.061153 -0.112373"/>
    <geometry>
      <mesh filename="package://improvedesign_description/meshes/kneepin3.stl" scale="0.001 0.001 0.001"/>
    </geometry>
  </collision>
</link>

<link name="thighpin3">
  <inertial>
    <origin rpy="0 0 0" xyz="-1.2701869583908731e-07 -5.661035953896665e-08 2.56607885634752e-07"/>
    <mass value="0.0024661502330680925"/>
    <inertia ixx="0.0" ixy="0.0" ixz="0.0" iyy="0.0" iyz="0.0" izz="0.0"/>
  </inertial>
  <visual>
    <origin rpy="0 0 0" xyz="-0.10742 -0.063751 -0.228373"/>
    <geometry>
      <mesh filename="package://improvedesign_description/meshes/thighpin3.stl" scale="0.001 0.001 0.001"/>
    </geometry>
    <material name="silver"/>
  </visual>
  <collision>
    <origin rpy="0 0 0" xyz="-0.10742 -0.063751 -0.228373"/>
    <geometry>
      <mesh filename="package://improvedesign_description/meshes/thighpin3.stl" scale="0.001 0.001 0.001"/>
    </geometry>
  </collision>
</link>

<link name="kneepin4">
  <inertial>
    <origin rpy="0 0 0" xyz="1.2732886342514682e-07 5.678943512665846e-08 2.513030722406384e-07"/>
    <mass value="0.0024661502330680925"/>
    <inertia ixx="0.0" ixy="0.0" ixz="0.0" iyy="0.0" iyz="0.0" izz="0.0"/>
  </inertial>
  <visual>
    <origin rpy="0 0 0" xyz="0.10742 0.063751 -0.112373"/>
    <geometry>
      <mesh filename="package://improvedesign_description/meshes/kneepin4.stl" scale="0.001 0.001 0.001"/>
    </geometry>
    <material name="silver"/>
  </visual>
  <collision>
    <origin rpy="0 0 0" xyz="0.10742 0.063751 -0.112373"/>
    <geometry>
      <mesh filename="package://improvedesign_description/meshes/kneepin4.stl" scale="0.001 0.001 0.001"/>
    </geometry>
  </collision>
</link>

<link name="thighpin4">
  <inertial>
    <origin rpy="0 0 0" xyz="1.270191485464034e-07 1.3282197449532296e-07 2.5660788557924086e-07"/>
    <mass value="0.002466150233068092"/>
    <inertia ixx="0.0" ixy="0.0" ixz="0.0" iyy="0.0" iyz="-0.0" izz="0.0"/>
  </inertial>
  <visual>
    <origin rpy="0 0 0" xyz="0.10892 0.061153 -0.228373"/>
    <geometry>
      <mesh filename="package://improvedesign_description/meshes/thighpin4.stl" scale="0.001 0.001 0.001"/>
    </geometry>
    <material name="silver"/>
  </visual>
  <collision>
    <origin rpy="0 0 0" xyz="0.10892 0.061153 -0.228373"/>
    <geometry>
      <mesh filename="package://improvedesign_description/meshes/thighpin4.stl" scale="0.001 0.001 0.001"/>
    </geometry>
  </collision>
</link>

<link name="kneepin5">
  <inertial>
    <origin rpy="0 0 0" xyz="1.2670898096034389e-07 -5.643154575574183e-08 2.5130307219900505e-07"/>
    <mass value="0.0024661502330680938"/>
    <inertia ixx="0.0" ixy="-0.0" ixz="0.0" iyy="0.0" iyz="0.0" izz="0.0"/>
  </inertial>
  <visual>
    <origin rpy="0 0 0" xyz="0.10742 -0.063751 -0.112373"/>
    <geometry>
      <mesh filename="package://improvedesign_description/meshes/kneepin5.stl" scale="0.001 0.001 0.001"/>
    </geometry>
    <material name="silver"/>
  </visual>
  <collision>
    <origin rpy="0 0 0" xyz="0.10742 -0.063751 -0.112373"/>
    <geometry>
      <mesh filename="package://improvedesign_description/meshes/kneepin5.stl" scale="0.001 0.001 0.001"/>
    </geometry>
  </collision>
</link>

<link name="thighpin5">
  <inertial>
    <origin rpy="0 0 0" xyz="1.2701869579745395e-07 -1.3282171296841172e-07 2.566078855514853e-07"/>
    <mass value="0.0024661502330680938"/>
    <inertia ixx="0.0" ixy="-0.0" ixz="0.0" iyy="0.0" iyz="-0.0" izz="0.0"/>
  </inertial>
  <visual>
    <origin rpy="0 0 0" xyz="0.10892 -0.061153 -0.228373"/>
    <geometry>
      <mesh filename="package://improvedesign_description/meshes/thighpin5.stl" scale="0.001 0.001 0.001"/>
    </geometry>
    <material name="silver"/>
  </visual>
  <collision>
    <origin rpy="0 0 0" xyz="0.10892 -0.061153 -0.228373"/>
    <geometry>
      <mesh filename="package://improvedesign_description/meshes/thighpin5.stl" scale="0.001 0.001 0.001"/>
    </geometry>
  </collision>
</link>

<link name="kneepin6">
  <inertial>
    <origin rpy="0 0 0" xyz="-5.0306980803327406e-17 -1.8907444489235647e-07 2.5130307221288284e-07"/>
    <mass value="0.0024661502330680916"/>
    <inertia ixx="0.0" ixy="-0.0" ixz="0.0" iyy="0.0" iyz="0.0" izz="0.0"/>
  </inertial>
  <visual>
    <origin rpy="0 0 0" xyz="-0.0015 -0.124904 -0.112373"/>
    <geometry>
      <mesh filename="package://improvedesign_description/meshes/kneepin6.stl" scale="0.001 0.001 0.001"/>
    </geometry>
    <material name="silver"/>
  </visual>
  <collision>
    <origin rpy="0 0 0" xyz="-0.0015 -0.124904 -0.112373"/>
    <geometry>
      <mesh filename="package://improvedesign_description/meshes/kneepin6.stl" scale="0.001 0.001 0.001"/>
    </geometry>
  </collision>
</link>

<link name="thighpin6">
  <inertial>
    <origin rpy="0 0 0" xyz="-2.5804011705155006e-17 -1.894320727086063e-07 2.56607885634752e-07"/>
    <mass value="0.002466150233068092"/>
    <inertia ixx="0.0" ixy="0.0" ixz="0.0" iyy="0.0" iyz="-0.0" izz="0.0"/>
  </inertial>
  <visual>
    <origin rpy="0 0 0" xyz="0.0015 -0.124904 -0.228373"/>
    <geometry>
      <mesh filename="package://improvedesign_description/meshes/thighpin6.stl" scale="0.001 0.001 0.001"/>
    </geometry>
    <material name="silver"/>
  </visual>
  <collision>
    <origin rpy="0 0 0" xyz="0.0015 -0.124904 -0.228373"/>
    <geometry>
      <mesh filename="package://improvedesign_description/meshes/thighpin6.stl" scale="0.001 0.001 0.001"/>
    </geometry>
  </collision>
</link>

<joint name="Rev1" type="revolute">
  <origin rpy="0 0 0" xyz="0.0 0.0 -0.116"/>
  <parent link="upperleg1"/>
  <child link="lowerleg1"/>
  <axis xyz="-0.01 -0.0 0.0"/>
  <limit effort="100" lower="-0.785398" upper="0.0" velocity="10"/>
</joint>

<joint name="Rev2" type="revolute">
  <origin rpy="0 0 0" xyz="0.0 0.0 -0.116"/>
  <parent link="lowerleg2"/>
  <child link="upperleg2"/>
  <axis xyz="-0.005 -0.00866 0.0"/>
  <limit effort="100" lower="-0.785398" upper="0.0" velocity="10"/>
</joint>

<joint name="Rev3" type="revolute">
  <origin rpy="0 0 0" xyz="0.0 0.0 -0.116"/>
  <parent link="upperleg4"/>
  <child link="lowerleg4"/>
  <axis xyz="-0.005 0.00866 -0.0"/>
  <limit effort="100" lower="-0.785398" upper="0.0" velocity="10"/>
</joint>

<joint name="Rev4" type="revolute">
  <origin rpy="0 0 0" xyz="0.0 0.0 -0.116"/>
  <parent link="upperleg3"/>
  <child link="lowerleg3"/>
  <axis xyz="-0.005 0.00866 -0.0"/>
  <limit effort="100" lower="0.0" upper="0.785398" velocity="10"/>
</joint>

<joint name="Rev5" type="revolute">
  <origin rpy="0 0 0" xyz="0.0 0.0 -0.116"/>
  <parent link="upperleg6"/>
  <child link="lowerleg6"/>
  <axis xyz="-0.01 0.0 -0.0"/>
  <limit effort="100" lower="0.0" upper="0.785398" velocity="10"/>
</joint>

<joint name="Rev6" type="revolute">
  <origin rpy="0 0 0" xyz="0.0 0.0 -0.116"/>
  <parent link="upperleg5"/>
  <child link="lowerleg5"/>
  <axis xyz="-0.005 -0.00866 0.0"/>
  <limit effort="100" lower="0.0" upper="0.785398" velocity="10"/>
</joint>

<joint name="Rev7" type="revolute">
  <origin rpy="0 0 0" xyz="-0.0015 0.124904 0.228373"/>
  <parent link="base_link"/>
  <child link="upperleg6"/>
  <axis xyz="0.01 0.0 -0.0"/>
  <limit effort="100" lower="0.0" upper="0.785398" velocity="10"/>
</joint>

<joint name="Rev8" type="revolute">
  <origin rpy="0 0 0" xyz="0.10742 0.063751 0.228373"/>
  <parent link="base_link"/>
  <child link="upperleg3"/>
  <axis xyz="0.005 -0.00866 0.0"/>
  <limit effort="100" lower="0.0" upper="0.785398" velocity="10"/>
</joint>

<joint name="Rev9" type="revolute">
  <origin rpy="0 0 0" xyz="-0.0015 -0.124904 0.228373"/>
  <parent link="base_link"/>
  <child link="upperleg1"/>
  <axis xyz="0.01 0.0 -0.0"/>
  <limit effort="100" lower="-0.785398" upper="0.0" velocity="10"/>
</joint>

<joint name="Rev10" type="revolute">
  <origin rpy="0 0 0" xyz="-0.10892 0.061153 0.228373"/>
  <parent link="base_link"/>
  <child link="upperleg5"/>
  <axis xyz="0.005 0.00866 -0.0"/>
  <limit effort="100" lower="0.0" upper="0.785398" velocity="10"/>
</joint>

<joint name="Rev11" type="revolute">
  <origin rpy="0 0 0" xyz="0.10742 -0.063751 0.228373"/>
  <parent link="base_link"/>
  <child link="lowerleg2"/>
  <axis xyz="0.005 0.00866 -0.0"/>
  <limit effort="100" lower="-0.785398" upper="0.0" velocity="10"/>
</joint>

<joint name="Rev12" type="revolute">
  <origin rpy="0 0 0" xyz="-0.10892 -0.061153 0.228373"/>
  <parent link="base_link"/>
  <child link="upperleg4"/>
  <axis xyz="0.005 -0.00866 0.0"/>
  <limit effort="100" lower="-0.785398" upper="0.0" velocity="10"/>
</joint>

<joint name="Rigid13" type="fixed">
  <origin rpy="0 0 0" xyz="0.003 0.0 0.0"/>
  <parent link="lowerleg1"/>
  <child link="kneepin1"/>
</joint>

<joint name="Rigid14" type="fixed">
  <origin rpy="0 0 0" xyz="0.0 0.0 0.0"/>
  <parent link="upperleg1"/>
  <child link="thighpin1"/>
</joint>

<joint name="Rigid15" type="fixed">
  <origin rpy="0 0 0" xyz="0.0015 0.002598 0.0"/>
  <parent link="upperleg2"/>
  <child link="thighpin2"/>
</joint>

<joint name="Rigid16" type="fixed">
  <origin rpy="0 0 0" xyz="0.0 0.0 0.0"/>
  <parent link="lowerleg2"/>
  <child link="kneepin2"/>
</joint>

<joint name="Rigid17" type="fixed">
  <origin rpy="0 0 0" xyz="0.0015 -0.002598 0.0"/>
  <parent link="lowerleg3"/>
  <child link="kneepin3"/>
</joint>

<joint name="Rigid18" type="fixed">
  <origin rpy="0 0 0" xyz="0.0 0.0 0.0"/>
  <parent link="upperleg3"/>
  <child link="thighpin3"/>
</joint>

<joint name="Rigid19" type="fixed">
  <origin rpy="0 0 0" xyz="0.0015 -0.002598 0.0"/>
  <parent link="lowerleg4"/>
  <child link="kneepin4"/>
</joint>

<joint name="Rigid20" type="fixed">
  <origin rpy="0 0 0" xyz="0.0 0.0 0.0"/>
  <parent link="upperleg4"/>
  <child link="thighpin4"/>
</joint>

<joint name="Rigid21" type="fixed">
  <origin rpy="0 0 0" xyz="0.0015 0.002598 0.0"/>
  <parent link="lowerleg5"/>
  <child link="kneepin5"/>
</joint>

<joint name="Rigid22" type="fixed">
  <origin rpy="0 0 0" xyz="0.0 0.0 0.0"/>
  <parent link="upperleg5"/>
  <child link="thighpin5"/>
</joint>

<joint name="Rigid23" type="fixed">
  <origin rpy="0 0 0" xyz="0.003 0.0 0.0"/>
  <parent link="lowerleg6"/>
  <child link="kneepin6"/>
</joint>

<joint name="Rigid24" type="fixed">
  <origin rpy="0 0 0" xyz="0.0 0.0 0.0"/>
  <parent link="upperleg6"/>
  <child link="thighpin6"/>
</joint>

</robot>
